Workbook

Sheet InfoInicial
A1: ESTA PLANILLA PUEDE SER UTILIZADA SOLAMENTE PARA EL TRABAJO PRACTICO: | E1: 6
G2: Reglas y consideraciones a tener en cuenta antes de entregar para corregir
A3: Tasa porcentual de IVA | B3: 0.21 | G3: 1. TODAS las celdas que tomen datos de otra parte del archivo deben estar linkeadas con una FÓRMULA. No se corregirán TPs con datos escritos como valores (esto vale incluso para la tasa de HD, IG e IVA). Tampoco se aceptarán fórmulas que hagan referencia a otros archivos.
A4: Tasa porcentual de Impuesto a las Ganancias | B4: 0.35
A5: Honorarios al Directorio | B5: 0.078 | C5: Variable sobre Utilidad económica antes de HD e IG
A7: Tiempo de Amortización Activos Fijos: | B7: Se considera una depreciación lineal y un valor residual nulo | G7: 2. TODOS los valores que se ingresen al archivo por primera vez deben tener su respectiva referencia o FUENTE (ej. cálculos auxiliares en otra hoja, links, etc.)
A8: edificios y obras complementarias | B8: 30 | C8: años
A9: instalaciones industriales | B9: 10 | C9: años | G9: 3. Los datos utilizados tienen que tener concordancia con los dimensionamientos anteriores.
A10: máquinas, equipos y accesorios | B10: 10 | C10: años | G10: 4. El SET "A" de verificaciones en la hoja “E-Form” debe estar OK antes de entregar una primer versión para corregir.
A11: rodados y equipos auxiliares | B11: 5 | C11: años
A12: muebles y útiles | B12: 5 | C12: años | G12: 5. El SET "A", “B” y “C” de verificaciones en la hoja “F-Form” debe estar OK antes de la entrega final
A13: Otros Activos y Cargos Diferidos | B13: 5 | C13: años
A14: Imprevistos | B14: 0.097
A16: Nombre del Producto | B16: Válvula mariposa sanitaria de acero inoxidable
A18: Ventas Anuales Promedio | B18: 44800 | C18: en Unidades
A19: Precio Promedio | B19: 110000 | C19: en $
A21: Cantidad de personal total
A22: en Producción | B22: 16 | C22: personas
A23: en Comercialización | B23: 5 | C23: personas
A24: en Administración | B24: 4 | C24: personas
A26: Tamaño de la planta en metros cuadrados | B26: 2500 | C26: m2
A27: Periodo de Instalación | B27: 12 | C27: en meses
A28: Período de Puesta en Marcha | B28: 4 | C28: en meses
A31: Tasa de Cambio | B31: 1300 | C31: $ por cada | D31: 1 | E31: U$S
A34: Tasa de Credito Bancario | B34: 65 | C34: anual
A35: Rubro a financiar | B35: Metalúrgico | G35: Año 6
A36: % sobre el total del Rubro | B36: 50
A38: Dias de Financiación de Proveedores | B38: 30
A39: % sobre Compras | B39: 50
A40: Tasa de financiación | B40: 30 | C40: anual
K234: Miguelito

Sheet E-Inv AF y Am
A1: ESTA PLANILLA PUEDE SER UTILIZADA SOLAMENTE PARA EL TRABAJO PRACTICO | E1: =InfoInicial!E1 -> 6
A3: Inversión Inicial en Activo Fijo | B3: Gasto interno (en $) | D3: Gasto Externo (en $)
B4: Año 0 | C4: Año 1 | D4: Año 0 | E4: Año 1
A6: a) Bienes de Uso
A7: Terreno y sus mejoras | B7: ='C. Aux. - Inv AF y Am'!C60*InfoInicial!B31 -> 211250000 | C7: 0 | D7: 0 | E7: 0
A8: Edificio y obras complementarias | B8: ='C. Aux. - Inv AF y Am'!B90 -> 975000000 | C8: 0 | D8: 0 | E8: 0
A9: Instalaciones industriales | B9: 0 | C9: 0 | D9: 0 | E9: 0
A10: Máquinas operativas
A11: importadas, valor FOB | D11: ='C. Aux. - Inv AF y Am'!D121*InfoInicial!B31 -> 694746000
A12: nacionales, precio en fábrica del proveedor
A13: Gastos conexos a la importación de maquinaria | D13: ='C. Aux. - Inv AF y Am'!C123*InfoInicial!B31 -> 95894500
A14: Transporte y montaje de la maquinaria | B14: ='C. Aux. - Inv AF y Am'!B125 -> 9000000
A15: Rodados y equipos auxiliares | B15: ='C. Aux. - Inv AF y Am'!D39 -> 17123903 | C15: 0 | D15: 0 | E15: 0
A16: Muebles y útiles* | B16: ='C. Aux. - Inv AF y Am'!D22 -> 8033066 | C16: 0 | D16: 0 | E16: 0
A17: Infraestructura en Redes y Telecomunicaciones | B17: ='C. Aux. - Inv AF y Am'!D72*1.5 -> 9528000 | C17: 0 | D17: 0 | E17: 0
A18: Infraestructura en predio propio | B18: ='C. Aux. - Inv AF y Am'!B82*1.5 -> 7687500 | C18: 0 | D18: 0 | E18: 0
A19: Imprevistos | B19: =SUM(B7:B18)*InfoInicial!B14 -> 1.2004938e+08 | D19: =SUM(D7:D18)*InfoInicial!B14 -> 76692128
A21: Total Bienes de uso | B21: =SUM(B7:B19) -> 1.3576718e+09 | D21: =SUM(D7:D19) -> 8.6733263e+08
A23: b) Gastos asimilables o cargos diferidos
A24: Investigaciones y estudios | B24: ='C. Aux. - Inv AF y Am'!C108 -> 32500000
A25: Constitución y organización de la empresa | B25: ='C. Aux. - Inv AF y Am'!B135 -> 1224000
A26: Gastos de Admin. e Ing. En en período de Instalación
A27: Gastos de puesta en marcha (AL AÑO 1) | B27: 0 | C27: ='CÁLCULOS MP'!F104*InfoInicial!B31 -> 3.4546504e+08
A28: Patentes y Licencias | B28: ='C. Aux. - Inv AF y Am'!B105+'C. Aux. - Inv AF y Am'!C99 -> 22282000
A29: Publicidad y Marca | B29: ='C. Aux. - Inv AF y Am'!B51+'C. Aux. - Inv AF y Am'!B52 -> 2120000
A30: Infraestructura en predio ajeno | B30: 0
A31: Imprevistos | B31: =SUM(B24:B30)*InfoInicial!B5 -> 4533828 | C31: =SUM(C24:C30)*InfoInicial!C4 -> 0
A33: Total gastos asimilables o cargos diferidos | B33: =SUM(B24:B31) -> 62659828 | C33: =SUM(C24:C31) -> 3.4546504e+08
A35: c) Total Inversiones iniciales Activo Fijo, sin IVA | B35: =B21+B33 -> 1.4203317e+09 | C35: =C33+C21 -> 3.4546504e+08 | D35: =D33+D21 -> 8.6733263e+08 | E35: =E33+E21 -> 0
A36: d) IVA | B36: =B35*InfoInicial!B3 -> 2.9826965e+08 | C36: =C35*InfoInicial!B3 -> 72547658 | D36: =D35*InfoInicial!B3 -> 1.8213985e+08 | E36: =E35*InfoInicial!B3 -> 0
A38: e) TOTAL INVERSIONES INICIALES ACTIVO FIJO | B38: =B35+B36 -> 1.7186013e+09 | C38: =C35+C36 -> 4.1801269e+08 | D38: =D35+D36 -> 1.0494725e+09 | E38: =E35+E36 -> 0
A39: *Incluye depósito, matafuegos, etc.
A41: Rubro | B41: Inversión | C41: Coeficiente | D41: Alícuotas de amortización | G41: Valor residual
B42: original | D42: Años 1/3 | E42: Años 4/5
A43: Bienes de Uso
A45: Infraestructura en Redes y Telecomunicaciones | B45: =B17 -> 9528000 | G45: =B45 -> 9528000
A46: Infraestructura en predio propio | B46: =B18 -> 7687500 | G46: =B46 -> 7687500
A47: Terreno y sus mejoras | B47: =B7 -> 211250000 | G47: =B47-D47*3-E47*2 -> 211250000
A48: Edificio y obras complementarias | B48: =B8 -> 975000000 | C48: 0.03 | D48: =B48/30 -> 32500000 | E48: =B48/30 -> 32500000 | G48: =B48-D48*5 -> 812500000
A49: Instalaciones industriales | C49: 0.1 | D49: =B49/10 -> 0 | E49: =B49/10 -> 0 | G49: =B49-D49*3-E49*2 -> 0
...

Sheet C. Aux. - Inv AF y Am
A1: MUEBLES Y ÚTILES
A2: CONCEPTO | B2: CANTIDAD | C2: PRECIO UNITARIO | D2: TOTAL | E2: LINK
A3: Ventiladores | B3: 3 | C3: 134679 | D3: =B3*C3 -> 404037 | E3: https://www.mercadolibre.com.ar/ventilador-industrial-2-en-1-pie-pared-30-pulgadas-hamers-international-por-kacemaster-hi-180/p/MLA28530583#polycard_client=search-nordic&searchVariation=MLA28530583&backend_model=search-backend&wid=MLA1477985933&position=6&search_layout=grid&type=product&tracking_id=71c6694a-933b-4410-b2a0-4ecbe665bfed&sid=search
A4: Cesto de basura | B4: 12 | C4: 29334 | D4: =B4*C4 -> 352008 | E4: https://www.mercadolibre.com.ar/tacho-cesto-basura-residuos-70lt-florida/p/MLA23829534#polycard_client=search-nordic&searchVariation=MLA23829534&wid=MLA2271277652&position=16&search_layout=grid&type=product&tracking_id=af76bd0f-a8eb-4f24-9f07-c4ab71de3243&sid=search
A5: Mesas | B5: 4 | C5: 81299 | D5: =B5*C5 -> 325196 | E5: https://www.mercadolibre.com.ar/mesa-comedor-sala-madera-maciza-moderna-recta-120x80-sajo-tapa-natural/p/MLA35012645#polycard_client=search-nordic&searchVariation=MLA35012645&wid=MLA1418200317&position=4&search_layout=grid&type=product&tracking_id=66e5ed12-2013-47e0-86f6-e4ab8ed83d19&sid=search
A6: Sillas | B6: 16 | C6: 34484 | D6: =B6*C6 -> 551744 | E6: https://articulo.mercadolibre.com.ar/MLA-1124805067-juego-de-comedor-sillas-4-fajas-_JM?searchVariation=174238678815&pdp_filters=price%3A*-100000#polycard_client=search-nordic&searchVariation=174238678815&position=31&search_layout=grid&type=item&tracking_id=e1b67c4c-af20-4307-b6d8-7b5e34a787cd
A7: Vajilla | B7: 2 | C7: 20076 | D7: =B7*C7 -> 40152 | E7: https://www.mercadolibre.com.ar/set-de-vajilla-x-12-durax-plato-forjado-vaso-lunita-color-transparente/p/MLA52843818#polycard_client=search-nordic&searchVariation=MLA52843818&wid=MLA2186178562&position=5&search_layout=grid&type=product&tracking_id=c1110d7d-01ca-4c87-bc00-8ed6602c3c3d&sid=search
A8: Mesada | B8: 1 | C8: 168556 | D8: =B8*C8 -> 168556 | E8: https://www.mercadolibre.com.ar/mesada-cocina-de-acero-inoxidable-160x052-con-bacha-doble/p/MLA37524426#polycard_client=search-nordic&searchVariation=MLA37524426&wid=MLA2085610346&position=4&search_layout=grid&type=product&tracking_id=0932ea22-4e37-446e-a16c-a07cc711af3f&sid=search
A9: Escritorio | B9: 15 | C9: 65999 | D9: =B9*C9 -> 989985 | E9: https://www.mercadolibre.com.ar/escritorio-mesa-de-trabajo-home-collection-melamina-1-cajon-color-nevadoeverest/p/MLA25772158#polycard_client=search-nordic&searchVariation=MLA25772158&wid=MLA1398196809&position=23&search_layout=grid&type=product&tracking_id=a45b7b62-b275-469c-adab-bba7621b39df&sid=search
A10: Cajoneras | B10: 12 | C10: 80999 | D10: =B10*C10 -> 971988 | E10: https://www.mercadolibre.com.ar/chifonier-cajonera-dakar-zero-4-cajones-melamina-color-venezia/p/MLA28697087#polycard_client=search-nordic&searchVariation=MLA28697087&wid=MLA1905637978&position=4&search_layout=grid&type=product&tracking_id=2d4fad02-85af-41e8-9408-0340c14f6097&sid=search
A11: Mesa | B11: 5 | C11: 65999 | D11: =B11*C11 -> 329995 | E11: https://www.mercadolibre.com.ar/escritorio-mesa-de-trabajo-home-collection-melamina-1-cajon-color-nevadoeverest/p/MLA25772158#polycard_client=search-nordic&searchVariation=MLA25772158&wid=MLA1398196809&position=23&search_layout=grid&type=product&tracking_id=a45b7b62-b275-469c-adab-bba7621b39df&sid=search
A12: Sillas ergonómicas | B12: 14 | C12: 72584 | D12: =B12*C12 -> 1016176 | E12: https://www.mercadolibre.com.ar/silla-de-oficina-pc-ejecutiva-escritorio-lumbar-blanca-zhome-color-blanco-material-del-tapizado-malla-z-103-b/p/MLA42445941#polycard_client=search-nordic&searchVariation=MLA42445941&wid=MLA1964272712&position=7&search_layout=grid&type=product&tracking_id=4e62f608-2610-47b0-95af-99312d3e9ea2&sid=search
A13: Pizarras | B13: 2 | C13: 47990 | D13: =B13*C13 -> 95980 | E13: https://www.mercadolibre.com.ar/pizarraspremium-pizarra-blanca-magnetica-multiuso-80x120cm-marco-pvc/p/MLA23839169#polycard_client=search-nordic&searchVariation=MLA23839169&wid=MLA1472131439&position=5&search_layout=grid&type=product&tracking_id=c12a4fc5-bcee-479b-8dbe-ceab27117bf4&sid=search
A14: Inodoros con mochila | B14: 6 | C14: 188516 | D14: =B14*C14 -> 1131096 | E14: https://www.mercadolibre.com.ar/inodoro-corto-ferrum-mochila-asiento-deposito-simple-color-blanco/p/MLA50845595#polycard_client=search-nordic&searchVariation=MLA50845595&wid=MLA2215256670&position=4&search_layout=grid&type=product&tracking_id=baa560b3-be5e-4d43-85fe-06829ed36ee3&sid=search
A15: Lavamanos | B15: 4 | C15: 75241 | D15: =B15*C15 -> 300964 | E15: https://articulo.mercadolibre.com.ar/MLA-1863892946-bacha-roca-loza-de-colgar-1-agujero-con-griferia-monocomando-_JM?searchVariation=181217673610#polycard_client=search-nordic&searchVariation=181217673610&position=57&search_layout=grid&type=item&tracking_id=dea5c3a7-4839-4eaa-9983-bf1998a2dcdd
A16: Lockers | B16: 12 | C16: 612628 | D16: =C16 -> 612628 | E16: https://articulo.mercadolibre.com.ar/MLA-1426467169-lockers-metalicos-16-puertas-con-cerradura-reforzado-_JM?searchVariation=182767673083#is_advertising=true&searchVariation=182767673083&backend_model=search-backend&position=1&search_layout=grid&type=pad&tracking_id=ad2e654e-c51b-451e-8f1d-432ff849d01c&is_advertising=true&ad_domain=VQCATCORE_LST&ad_position=1&ad_click_id=MTNhZGQ4ODEtOTY5OC00M2FlLTljZDctMjkxZDFkMmNhNWU4
A17: Espejos | B17: 4 | C17: 23991 | D17: =B17*C17 -> 95964 | E17: https://articulo.mercadolibre.com.ar/MLA-2009868240-espejo-50-cm-bano-redondo-circular-_JM?searchVariation=186863106697#polycard_client=search-nordic&searchVariation=186863106697&position=38&search_layout=grid&type=item&tracking_id=3b35a17a-d86b-419c-b8e4-f78917b25142
A18: Duchas | B18: 2 | C18: 9390 | D18: =B18*C18 -> 18780 | E18: https://www.mercadolibre.com.ar/flor-ducha-cuadrada-acero-inoxidable-brazo-cano-cromado-color-gris/p/MLA34134266?pdp_filters=item_id:MLA1807778750#wid=MLA1807778750&sid=search&is_advertising=true&searchVariation=MLA34134266&backend_model=search-backend&position=1&search_layout=grid&type=pad&tracking_id=4a4c48dd-1490-41e8-8de7-2a4c12e7156a&is_advertising=true&ad_domain=VQCATCORE_LST&ad_position=1&ad_click_id=NTEzNDE0OTctYjEyMC00MDk1LWFhNGUtZWRlOWE0YmYzZDg1
A19: Mingitorios | B19: 2 | C19: 54625 | D19: =B19*C19 -> 109250 | E19: https://www.mercadolibre.com.ar/mingitorio-oval-piazza-b0601-loza-blanco-urinario-sanitario/p/MLA37737585#polycard_client=search-nordic&searchVariation=MLA37737585&wid=MLA1831629870&position=13&search_layout=grid&type=product&tracking_id=af85aa43-c4f1-4e24-8460-1c5336a15a3a&sid=search
A20: Articulos de libreria | B20: 64 | C20: 98164 | D20: =C20*2 -> 196328 | E20: https://articulo.mercadolibre.com.ar/MLA-1124027479-set-utiles-libreria-articulos-oficina-escritorio-kit-empresa-_JM#polycard_client=search-nordic&position=22&search_layout=grid&type=item&tracking_id=8962efd5-362f-4597-a02d-595a55f1ff39&wid=MLA1124027479&sid=search
A21: Herramientas | B21: 12 | C21: 322239 | D21: =C21 -> 322239 | E21: https://articulo.mercadolibre.com.ar/MLA-789232631-valija-aluminio-187-pz-herramientas-y-tubos-la-mas-completa-_JM?searchVariation=61941586109#polycard_client=search-nordic&searchVariation=61941586109&position=17&search_layout=grid&type=item&tracking_id=edf4c3fc-0536-4f9c-9597-227f1ce3f421
C22: TOTAL | D22: =SUM(D3:D21) -> 8033066
A24: EQUIPOS AUXILIARES
A25: CONCEPTO | B25: CANTIDAD | C25: PRECIO UNITARIO | D25: TOTAL | E25: LINK
A26: Carteles de señalización | B26: 10 | C26: 2831 | D26: =B26*C26 -> 28310 | E26: https://www.mercadolibre.com.ar/cartel-senalizacion-industrial-modelos-22x28-ever-safe-color-matafuego/p/MLA52220717#polycard_client=search-nordic&searchVariation=MLA52220717&wid=MLA2185827974&position=18&search_layout=grid&type=product&tracking_id=0240d003-55c1-4f1e-a8df-7cecd2bb7534&sid=search
A27: Teléfonos | B27: 14 | C27: 21500 | D27: =B27*C27 -> 301000 | E27: https://www.mercadolibre.com.ar/telefono-fijo-de-mesa-pared-cableado-casa-numeros-grandes-libercam-phon-30-color-negro/p/MLA26360634?pdp_filters=item_id:MLA1480424714#wid=MLA1480424714&sid=search&is_advertising=true&searchVariation=MLA26360634&backend_model=search-backend&position=2&search_layout=stack&type=pad&tracking_id=5f679f02-8833-44e3-87db-24b653d43fd9&is_advertising=true&ad_domain=VQCATCORE_LST&ad_position=2&ad_click_id=MTljMDY3OTctY2QwZi00MDMxLTlmZGQtOGY4NjEwZmU1Y2Vh
A28: Matafuegos ABC | B28: 6 | C28: 89179 | D28: =B28*C28 -> 535074 | E28: https://articulo.mercadolibre.com.ar/MLA-620271506-matafuegos-nuevos-polvo-triclase-5-kg-tarjeta-soporte-baliza-_JM?searchVariation=15873553124#is_advertising=true&searchVariation=15873553124&backend_model=search-backend&position=3&search_layout=grid&type=pad&tracking_id=be724187-60f5-4e51-a256-d4c073c9a6c3&is_advertising=true&ad_domain=VQCATCORE_LST&ad_position=3&ad_click_id=YmZkYTZmNTgtNmM0ZS00YWI5LWJjY2ItNjBkNjYwN2Q3NTI0
A29: Luces de emergencia | B29: 4 | C29: 14400 | D29: =B29*C29 -> 57600 | E29: https://articulo.mercadolibre.com.ar/MLA-1974041224-pack-2-luz-de-emergencia-bateria-recargable-60-led-industria-_JM?searchVariation=186391418629#is_advertising=true&searchVariation=186391418629&backend_model=search-backend&position=8&search_layout=grid&type=pad&tracking_id=607661ae-1f9b-4b22-a31d-58361221510b&is_advertising=true&ad_domain=VQCATCORE_LST&ad_position=8&ad_click_id=ZGU1YTM3MjYtMTY0MS00OGIyLTkxZmYtOWZiN2U3YTA0NTVl
A30: Dispenser de agua | B30: 4 | C30: 276749 | D30: =B30*C30 -> 1106996 | E30: https://articulo.mercadolibre.com.ar/MLA-736077407-dispenser-de-agua-frio-calor-conexion-a-red-premium-kit-_JM?searchVariation=188767880075#polycard_client=search-nordic&searchVariation=188767880075&position=21&search_layout=grid&type=item&tracking_id=e6d41f5b-3a42-4d30-9313-a15d92cc5846
A31: Botiquín primeros auxilios | B31: 6 | C31: 16872 | D31: =B31*C31 -> 101232 | E31: https://articulo.mercadolibre.com.ar/MLA-1485501109-botiquin-primeros-auxilios-30-elementos-eversafe-mol-madera-_JM#is_advertising=true&backend_model=search-backend&position=3&search_layout=grid&type=pad&tracking_id=f021687f-ea43-4d0c-9e68-253307cecea9&is_advertising=true&ad_domain=VQCATCORE_LST&ad_position=3&ad_click_id=YjNmYjQyMGMtYjQ4Yi00ZGNlLWI0ODUtNThlMzY0MGY4NjMz
A32: Microondas | B32: 4 | C32: 104799 | D32: =B32*C32 -> 419196 | E32: https://www.mercadolibre.com.ar/microondas-sansei-msarw20uap-rotativo-20l-700w/p/MLA43529502#polycard_client=search_best-seller&tracking_id=78d08ac2-7f3e-437f-9696-aff864c61617&wid=MLA1967730220&sid=search
A33: Heladera | B33: 1 | C33: 388778 | D33: =B33*C33 -> 388778 | E33: https://www.mercadolibre.com.ar/heladera-telefunken-300-lts-con-freezer-blanca-hd300b/p/MLA51643130#polycard_client=search-nordic&searchVariation=MLA51643130&wid=MLA2182060712&position=25&search_layout=stack&type=product&tracking_id=3af9a9a8-30e9-4f5b-b201-36219d10f4ab&sid=search
A34: Cafetera | B34: 4 | C34: 19049 | D34: =B34*C34 -> 76196 | E34: https://www.mercadolibre.com.ar/cafetera-electrica-de-filtro-sansei-casa9118bp-075l-color-negro/p/MLA27351867?pdp_filters=item_id:MLA1551426198#wid=MLA1551426198&sid=search&is_advertising=true&searchVariation=MLA27351867&backend_model=search-backend&position=1&search_layout=stack&type=pad&tracking_id=c94d15dc-6e57-4d25-a555-c3088b34b24d&is_advertising=true&ad_domain=VQCATCORE_LST&ad_position=1&ad_click_id=YjNmMGYxMmUtMTA0Zi00NWVlLWFmZDktZjI3ZjcxODUyOGVk
A35: Aire acondicionado | B35: 5 | C35: 619999 | D35: =B35*C35 -> 3099995 | E35: https://www.mercadolibre.com.ar/aire-acondicionado-sansei-split-ultra-friocalor-inverter-3500w3053fg/p/MLA25265609#polycard_client=search-nordic&searchVariation=MLA25265609&wid=MLA1514533665&position=38&search_layout=stack&type=product&tracking_id=e3aa563b-4da8-4c82-bf92-510c068c34ac&sid=search
A36: Computadoras | B36: 15 | C36: 631904 | D36: =B36*C36 -> 9478560 | E36: https://www.mercadolibre.com.ar/notebook-lenovo-ideapad-slim-156-intel-i3-8gb-ram-256gb-ssd-color-arctic-grey/p/MLA45361885#polycard_client=search-nordic&searchVariation=MLA45361885&wid=MLA2006890214&position=10&search_layout=stack&type=product&tracking_id=b904eb91-8bcb-424e-aba1-4fc7cc598428&sid=search
A37: Impresora | B37: 4 | C37: 163399 | D37: =B37*C37 -> 653596 | E37: https://www.mercadolibre.com.ar/impresora-multifuncion-hp-deskjet-ink-advantage-2875-wifi/p/MLA29022615#polycard_client=search_best-seller&tracking_id=d6d87091-7df5-4e4d-9985-2ee499254c67&wid=MLA1445106795&sid=search
A38: Zorra manual | B38: 2 | C38: 438685 | D38: =B38*C38 -> 877370 | E38: https://www.equustech.com.ar/productos/zorra-25-tn/
C39: TOTAL | D39: =SUM(D26:D38) -> 17123903
A41: zorra eléctrica | B41: 2525828 | C41: https://www.equustech.com.ar/productos/traspaletaelectrica2ton/
A42: zorra manual | B42: 438685 | C42: https://www.equustech.com.ar/productos/zorra-25-tn/
...

Sheet E-Costos
A3: ESTA PLANILLA PUEDE SER UTILIZADA SOLAMENTE PARA EL TRABAJO PRACTICO: | E3: =InfoInicial!E1 -> 6
A4: COSTO TOTAL DE PRODUCCION
B5: Gastos en el Area de Producción
A6: Rubros | B6: Año 1 | C6: Año 2 | D6: Año 3 | E6: Año 4 | F6: Año 5
A7: Materia prima | B7: =('CÁLCULOS MP'!F102)*InfoInicial!B31 -> 1.4898176e+09 | C7: =+'CÁLCULOS MP'!$B$78*InfoInicial!$B$31 -> 1.4444621e+09 | D7: =+'CÁLCULOS MP'!$B$78*InfoInicial!$B$31 -> 1.4444621e+09 | E7: =+'CÁLCULOS MP'!$B$78*InfoInicial!$B$31 -> 1.4444621e+09 | F7: =+'CÁLCULOS MP'!$B$78*InfoInicial!$B$31 -> 1.4444621e+09
A8: Mano de obra directa | B8: ='AUX - COSTO DE PRODUC'!B17 -> 1.2909486e+08 | C8: ='AUX - COSTO DE PRODUC'!$B$12 -> 1.4343874e+08 | D8: ='AUX - COSTO DE PRODUC'!$B$12 -> 1.4343874e+08 | E8: ='AUX - COSTO DE PRODUC'!$B$12 -> 1.4343874e+08 | F8: ='AUX - COSTO DE PRODUC'!$B$12 -> 1.4343874e+08
A9: Gastos de fabricación:
A10: Amortizaciones | B10: ='AUX - COSTO DE PRODUC'!$B$40 -> 1.4929805e+08 | C10: ='AUX - COSTO DE PRODUC'!$B$40 -> 1.4929805e+08 | D10: ='AUX - COSTO DE PRODUC'!$B$40 -> 1.4929805e+08 | E10: ='AUX - COSTO DE PRODUC'!$B$37 -> 1.4929805e+08 | F10: ='AUX - COSTO DE PRODUC'!$B$37 -> 1.4929805e+08
A11: Personal indirecto | B11: ='AUX - COSTO DE PRODUC'!$D$51 -> 136015992 | C11: ='AUX - COSTO DE PRODUC'!$D$51 -> 136015992 | D11: ='AUX - COSTO DE PRODUC'!$D$51 -> 136015992 | E11: ='AUX - COSTO DE PRODUC'!$D$51 -> 136015992 | F11: ='AUX - COSTO DE PRODUC'!$D$51 -> 136015992
A12: Materiales | B12: ='AUX - COSTO DE PRODUC'!$F$59 -> 58465765 | C12: ='AUX - COSTO DE PRODUC'!$G$59 -> 57988971 | D12: ='AUX - COSTO DE PRODUC'!$G$59 -> 57988971 | E12: ='AUX - COSTO DE PRODUC'!$G$59 -> 57988971 | F12: ='AUX - COSTO DE PRODUC'!$G$59 -> 57988971
A13: Energía eléctrica | B13: ='C. Aux. Costos'!B165 -> 47167836 | C13: ='C. Aux. Costos'!E157 -> 44809444 | D13: ='C. Aux. Costos'!E157 -> 44809444 | E13: ='C. Aux. Costos'!E157 -> 44809444 | F13: ='C. Aux. Costos'!E157 -> 44809444
A14: Combustibles | B14: 0 | C14: 0 | D14: 0 | E14: 0 | F14: 0
A15: Redes y Telecomunicaciones | B15: 0 | C15: 0 | D15: 0 | E15: 0 | F15: 0
A16: Tasas e impuestos | B16: ='C. Aux. Costos'!B60 -> 21937500 | C16: ='C. Aux. Costos'!B60 -> 21937500 | D16: ='C. Aux. Costos'!B60 -> 21937500 | E16: ='C. Aux. Costos'!B60 -> 21937500 | F16: ='C. Aux. Costos'!B60 -> 21937500
A17: Seguridad e Higiene | B17: 0 | C17: 0 | D17: 0 | E17: 0 | F17: 0
A18: Tratamiento de efluentes y subproductos | B18: 0 | C18: 0 | D18: 0 | E18: 0 | F18: 0
A19: Seguros | B19: ='C. Aux. Costos'!$E$263*0.9+'C. Aux. Costos'!$F$269 -> 24990084 | C19: ='C. Aux. Costos'!$E$263*0.9+'C. Aux. Costos'!$G$269 -> 24990084 | D19: ='C. Aux. Costos'!$E$263*0.9+'C. Aux. Costos'!$G$269 -> 24990084 | E19: ='C. Aux. Costos'!$E$263*0.9+'C. Aux. Costos'!$G$269 -> 24990084 | F19: ='C. Aux. Costos'!$E$263*0.9+'C. Aux. Costos'!$G$269 -> 24990084
A20: *libre para insertar costos adicionales*
A21: *libre para insertar costos adicionales*
A22: Imprevistos | B22: =SUM(B7:B16)*InfoInicial!$B$14 -> 1.9708436e+08 | C22: =SUM(C7:C16)*InfoInicial!$B$14 -> 1.9380123e+08 | D22: =SUM(D7:D16)*InfoInicial!$B$14 -> 1.9380123e+08 | E22: =SUM(E7:E16)*InfoInicial!$B$14 -> 1.9380123e+08 | F22: =SUM(F7:F16)*InfoInicial!$B$14 -> 1.9380123e+08
A23: Gastos Total de Producción | B23: =SUM(B7:B22) -> 2.253872e+09 | C23: =SUM(C7:C22) -> 2.2167421e+09 | D23: =SUM(D7:D22) -> 2.2167421e+09 | E23: =SUM(E7:E22) -> 2.2167421e+09 | F23: =SUM(F7:F22) -> 2.2167421e+09
A25: % Gasto Constante | B25: =(B10+B11+B16+B22)/B23 -> 0.22376422 | C25: =(C10+C11+C16+C22)/C23 -> 0.22603115 | D25: =(D10+D11+D16+D22)/D23 -> 0.22603115 | E25: =(E10+E11+E16+E22)/E23 -> 0.22603115 | F25: =(F10+F11+F16+F22)/F23 -> 0.22603115
A26: % Gasto Variable | B26: =(B7+B8+B12+B13)/B23 -> 0.76514816 | C26: =(C7+C8+C12+C13)/C23 -> 0.76269551 | D26: =(D7+D8+D12+D13)/D23 -> 0.76269551 | E26: =(E7+E8+E12+E13)/E23 -> 0.76269551 | F26: =(F7+F8+F12+F13)/F23 -> 0.76269551
B28: Gastos a activar
B29: Mercadería en Curso y Semielaborada | G29: Puesta en marcha
A30: Rubros | B30: Año 1 | C30: Año 2 | D30: Año 3 | E30: Año 4 | F30: Año 5 | G30: Año 1
A31: Materia prima | B31: ='CÁLCULOS MP'!$F$107*InfoInicial!$B$31 -> 25600511 | C31: ='CÁLCULOS MP'!F107*InfoInicial!B31 -> 25600511 | D31: ='C. Aux. Costos'!$C$215 -> 25600511 | E31: ='C. Aux. Costos'!$C$215 -> 25600511 | F31: ='C. Aux. Costos'!$C$215 -> 25600511 | G31: ='CÁLCULOS MP'!F104*InfoInicial!B31 -> 3.4546504e+08
A32: Mano de obra directa | B32: ='C. Aux. Costos'!$C$217 -> 2542195.5 | C32: ='C. Aux. Costos'!$C$217 -> 2542195.5 | D32: ='C. Aux. Costos'!$C$217 -> 2542195.5 | E32: ='C. Aux. Costos'!$C$217 -> 2542195.5 | F32: ='C. Aux. Costos'!$C$217 -> 2542195.5 | G32: =B8-'AUX - COSTO DE PRODUC'!B19 -> 12128257
A33: Gastos de fabricación:
A34: Amortizaciones | B34: ='C. Aux. Costos'!B189 -> 2084275.6 | C34: ='C. Aux. Costos'!B190 -> 1740277 | D34: ='C. Aux. Costos'!B190 -> 1740277 | E34: ='C. Aux. Costos'!B191 -> 1740277 | F34: ='C. Aux. Costos'!B191 -> 1740277 | G34: 0
A35: Personal indirecto | B35: ='C. Aux. Costos'!C208 -> 997150.3 | C35: ='C. Aux. Costos'!B208 -> 1005986.7 | D35: ='C. Aux. Costos'!B208 -> 1005986.7 | E35: ='C. Aux. Costos'!B208 -> 1005986.7 | F35: ='C. Aux. Costos'!B208 -> 1005986.7 | G35: 0
A36: Materiales | B36: ='C. Aux. Costos'!A215*SUM('AUX - COSTO DE PRODUC'!H54:H57) -> 1254338.6 | C36: ='C. Aux. Costos'!$A$215*SUM('AUX - COSTO DE PRODUC'!$I$54:$I$57) -> 1027751 | D36: ='C. Aux. Costos'!$A$215*SUM('AUX - COSTO DE PRODUC'!$I$54:$I$57) -> 1027751 | E36: ='C. Aux. Costos'!$A$215*SUM('AUX - COSTO DE PRODUC'!$I$54:$I$57) -> 1027751 | F36: ='C. Aux. Costos'!$A$215*SUM('AUX - COSTO DE PRODUC'!$I$54:$I$57) -> 1027751 | G36: ='AUX - COSTO DE PRODUC'!B60*B36 -> 125433.86
A37: Energía eléctrica | B37: ='C. Aux. Costos'!B172 -> 417982.83 | C37: ='C. Aux. Costos'!E164 -> 417982.83 | D37: ='C. Aux. Costos'!E164 -> 417982.83 | E37: ='C. Aux. Costos'!E164 -> 417982.83 | F37: ='C. Aux. Costos'!E164 -> 417982.83 | G37: ='C. Aux. Costos'!E168 -> 8146717
A38: Combustibles | B38: 0 | C38: 0 | D38: 0 | E38: 0 | F38: 0
A39: Redes y Telecomunicaciones | B39: 0 | C39: 0 | D39: 0 | E39: 0 | F39: 0
A40: Tasas e impuestos | B40: ='C. Aux. Costos'!D237 -> 192693.93 | C40: ='C. Aux. Costos'!D232 -> 194401.51 | D40: ='C. Aux. Costos'!D232 -> 194401.51 | E40: ='C. Aux. Costos'!D232 -> 194401.51 | F40: ='C. Aux. Costos'!D232 -> 194401.51
A41: Otros rubros
A42: Imprevistos | B42: =SUM(B31:B40)*InfoInicial!$B$14 -> 3209647.4 | C42: =SUM(C31:C40)*InfoInicial!$B$14 -> 3155323.3 | D42: =SUM(D31:D40)*InfoInicial!$B$14 -> 3155323.3 | E42: =SUM(E31:E40)*InfoInicial!$B$14 -> 3155323.3 | F42: =SUM(F31:F40)*InfoInicial!$B$14 -> 3155323.3
A43: Total gastos a activar | B43: =SUM(B31:B42) -> 36298795 | C43: =SUM(C31:C42) -> 35684429 | D43: =SUM(D31:D42) -> 35684429 | E43: =SUM(E31:E42) -> 35684429 | F43: =SUM(F31:F42) -> 35684429 | G43: =SUM(G31:G42) -> 3.6586544e+08
B45: Costo en el Area de Producción
...

Sheet C. Aux. Costos
A2: m3 de agua consumidos en producción: | B2: =2.5*350*8/1000 -> 7 | O2: PLAN DE VENTAS | Q2: P= | R2: 110000
A3: m3 de agua consumidos por empleados: | B3: 254 | O3: AÑO 1 | P3: AÑO 2 | Q3: AÑO 3 | R3: AÑO 4 | S3: AÑO 5
N4: cantidad ventas | O4: 36532 | P4: 44800 | Q4: 44800 | R4: 44800 | S4: 44800
A5: 1250 m2 + 7m alto | B5: =1250*7 -> 8750 | N5: P*Q | O5: =$R$2*O4 -> 4018520000 | P5: =$R$2*P4 -> 4928000000 | Q5: =$R$2*Q4 -> 4928000000 | R5: =$R$2*R4 -> 4928000000 | S5: =$R$2*S4 -> 4928000000
A6: Descripcion | B6: Precio | C6: Gasto Total | D6: Link
A7: Precio Agua ($/m3) | B7: 1141.87 | C7: =B7*(B3+B2) -> 298028.07 | D7: https://www.aysa.com.ar/tramites/Conoce-tu-factura | N7: PRODUCCION | O7: 36655 | P7: 44800 | Q7: 44800 | R7: 44800 | S7: 44800
A8: Precio gas ($/m3) | B8: 217 | C8: =B8*B5 -> 1898750
A9: Precio internet y linea | B9: 27790 | C9: =B9*12 -> 333480 | D9: https://www.telecom.com.ar/web/productos/internet | E9: Se divide equitativamente entre administración y comercialización
A10: TOTAL SERVICIOS MENSUAL | C10: =SUM(C7:C9) -> 2530258.1
A13: SUELDOS | B13: Basico/Mes | C13: Contribuciones | D13: Cantidad | E13: Total | F13: Aguinaldo
A14: Director general | B14: 3120000 | C14: ='C. Aux. Costos'!J30/100*B14 -> 929760 | D14: 1 | E14: =C14+B14 -> 4049760 | F14: =B14*D14 -> 3120000 | G14: Sueldo de director general divido en las 3 areas para calcular costos de cada area
A15: Personal de portería y seguridad | B15: 1008000 | C15: =0.258*B15 -> 260064 | D15: 2 | E15: =C15+B15 -> 1268064 | F15: =B15*D15 -> 2016000
A16: Personal de limpieza | B16: 785000 | C16: =0.258*B16 -> 202530 | D16: 3 | E16: =C16+B16 -> 987530 | F16: =B16*D16 -> 2355000
A17: Gerente Administrativo | B17: 2580000 | C17: =0.258*B17 -> 665640 | D17: 1 | E17: =C17+B17 -> 3245640 | F17: =B17*D17 -> 2580000
A18: Contador | B18: 1400000 | C18: =0.258*B18 -> 361200 | D18: 1 | E18: =C18+B18 -> 1761200 | F18: =B18*D18 -> 1400000
A19: Encargado de rrhh | B19: 1580000 | C19: =0.258*B19 -> 407640 | D19: 1 | E19: =C19+B19 -> 1987640 | F19: =B19*D19 -> 1580000
A20: Analista de compras | B20: 1890000 | C20: =0.258*B20 -> 487620 | D20: 1 | E20: =C20+B20 -> 2377620 | F20: =B20*D20 -> 1890000
A21: Gerente Comercial | B21: 2600000 | C21: =0.258*B21 -> 670800 | D21: 1 | E21: =C21+B21 -> 3270800 | F21: =B21*D21 -> 2600000
A22: Ejecutivo de ventas | B22: 1230000 | C22: =0.258*B22 -> 317340 | D22: 2 | E22: =C22+B22 -> 1547340 | F22: =B22*D22 -> 2460000
A23: Responsable logistica | B23: 2000000 | C23: =0.258*B23 -> 516000 | D23: 1 | E23: =C23+B23 -> 2516000 | F23: =B23*D23 -> 2000000
A24: Encargado posventa | B24: 1230000 | C24: =0.258*B24 -> 317340 | D24: 1 | E24: =C24+B24 -> 1547340 | F24: =B24*D24 -> 1230000
A25: Peones de carga y decarga - Depósito | B25: 945600 | C25: =0.258*B25 -> 243964.8 | D25: 2 | E25: =C25+B25 -> 1189564.8 | F25: =B25*D25 -> 1891200
A26: Gerente de produccion | B26: 2580000 | C26: =0.258*B26 -> 665640 | D26: 1 | E26: =C26+B26 -> 3245640 | F26: =B26*D26 -> 2580000
... A28: Responsable de prog de maquinas | B28: 950000 | C28: =0.258*B28 -> 245100 | D28: 1 | E28: =C28+B28 -> 1195100 | F28: =B28*D28 -> 950000
A29: Responsable de HSE y calidad | B29: 1450000 | C29: =0.258*B29 -> 374100 | D29: 1 | E29: =C29+B29 -> 1824100 | F29: =B29*D29 -> 1450000 | H29: Contribuciones | I29: ART | J29: Total
A30: Encargado de mantenimiento | B30: 1500000 | C30: =0.258*B30 -> 387000 | D30: 1 | E30: =C30+B30 -> 1887000 | F30: =B30*D30 -> 1500000 | H30: =16+2+6+1.5+0.3 -> 25.8 | I30: 4 | J30: =I30+H30 -> 29.8
A37: TOTAL | B37: =SUM(B14:B30) -> 27716600 | C37: =SUM(C14:C30) -> 7275682.8
C39: Aguinaldo | D39: Sueldo Anual | E39: Total
A40: Producción | B40: =SUM(D26:D30) -> 16 | C40: =SUM(F26:F30)+F14/3 -> 17936000 | D40: =(SUM(E26:E30)+E14/3)*12 -> 127124448 | E40: =C40+D40 -> 145060448
A41: Administración | B41: =SUM(D17:D20) -> 4 | C41: =SUM(F17:F20)+F14/3 -> 8490000 | D41: =(SUM(E27:E37)+E17/3)*12 -> 84960288 | E41: =C41+D41 -> 93450288
A42: Comercial | B42: =SUM(D21:D24) -> 5 | C42: =SUM(F21:F24)+F14/3 -> 9330000 | D42: =(SUM(E28:E38)+E18/3)*12 -> 65919200 | E42: =C42+D42 -> 75249200
A43: Total Personal | B43: =SUM(B40:B42) -> 25 | C43: =SUM(C40:C42) -> 35756000 | D43: =SUM(D40:D42) -> 278003936 | E43: =C43+D43 -> 313759936
B45: Salarios Promedio Bumeran | C45: https://www.bumeran.com.ar/salarios
B46: Salarios Reportados | C46: cuantogano.com/sueldos/logistica.html
A48: MANO OBRA DIRECTA:
A49: Operarios (12) + cargas y aguinaldo
A51: Amortizaciones | C51: años 1/3 | D51: Años 4/5
A52: Alicuota Anual | C52: ='E-Inv AF y Am'!D54 -> 1.3657937e+08 | D52: ='E-Inv AF y Am'!E54 -> 1.3657937e+08
A53: Area de producción le corresponde de todos los rubros: | C53: 0.9
A55: Tasas e impuestos PRODUCCIÓN:
...

Sheet AUX - COSTO DE PRODUC
A1: MANO DE OBRA
A2: cant de operarios | B2: 12
A3: JORNAL | B3: ='C. Aux. Costos'!B27/8/30 -> 3616.6667 | C3: $/hr
A4: CARGAS SOCIALES | B4: 25,8% Sobre el jornal básico
A5: adicionales (aguinaldos, premios, posibles horas extra) | B5: 50% sobre el básico
A7: horas trabajadas al año | B7: 1880 | C7: horas/año
A9: Costo por hora | B9: =B3+B3*0.258+B3*0.5 -> 6358.1 | C9: $/hr
A11: AÑOS RÉGIMEN
A12: TOTAL MdO | B12: =B7*B9*B2 -> 1.4343874e+08
A13: $/PT | B13: =B12/44800 -> 3201.7575
A15: AÑO 1 | B15: PRODUCCION AÑO 1 | C15: 36532
A17: Estimamos un 90% del total de MdO anual en régimen | B17: =B12*0.9 -> 1.2909486e+08
A19: MANO DE OBRA NETA | B19: =C15*B13 -> 1.169666e+08
A20: Volumen de MC y SE | B20: 794 | C20: PT
A21: MANO DE OBRA EN MC Y SE | B21: =B13*B20 -> 2542195.5
A24: TOTAL MDO AÑO 1 ESPERADO: | B24: =B19+B21 -> 1.195088e+08
A25: EXCESO DE MDO POR PEM: | B25: =B17-B19 -> 12128257
A28: GASTOS DE FABRICACIÓN
A29: AMORTIZACIONES DEL ÁREA DE FABRICACIÓN
A30: Máquinas operativas | B30: 1
A31: RODADOS Y EQUIPOS AUX | B31: 0
A32: MUEBLES Y ÚTILES | B32: 0.15
A33: IMPREVISTOS | B33: 0
A34: CARGOS DIFERIDOS | B34: ='E-Inv AF y Am'!C33/'E-Inv AF y Am'!B56 -> 0.84646898
A36: AÑOS 4/5
A37: Imputación anual | B37: ='E-Inv AF y Am'!E50+$B$32*'E-Inv AF y Am'!E52+$B$34*'E-Inv AF y Am'!E56 -> 1.4929805e+08
A39: AÑOS 1/3
A40: Imputación anual | B40: ='E-Inv AF y Am'!D50+$B$32*'E-Inv AF y Am'!D52+$B$34*'E-Inv AF y Am'!D56 -> 1.4929805e+08
A42: MANO DE OBRA INDIRECTA | B42: SALARIO MENSUAL (Con Cargas sociales) | C42: ASIGNACIÓN A PRODUCCIÓN | D42: TOTALES
A43: DIRECTOR GENERAL (1/3) | B43: ='C. Aux. Costos'!E14 -> 4049760 | C43: =1/3 -> 0.33333333 | D43: =C43*B43*12 -> 16199040
A44: GERENTE DE PRODUCCIÓN | B44: ='C. Aux. Costos'!E26 -> 3245640 | C44: 1 | D44: =C44*B44*12 -> 38947680
A45: RESPONSABLE DE PROGRAMACIÓN | B45: ='C. Aux. Costos'!E28 -> 1195100 | C45: 1 | D45: =C45*B45*12 -> 14341200
A46: RESPONSABLE CALIDAD Y SeH | B46: ='C. Aux. Costos'!E29 -> 1824100 | C46: 1 | D46: =C46*B46*12 -> 21889200
A47: ENCARGADO DE MANTENIMIENTO | B47: ='C. Aux. Costos'!E30 -> 1887000 | C47: 1 | D47: =C47*B47*12 -> 22644000
A48: PORTERÍA Y VIGILANCIA | B48: ='C. Aux. Costos'!E15*'C. Aux. Costos'!D15 -> 2536128 | C48: =1/3 -> 0.33333333 | D48: =C48*B48*12 -> 10144512
A49: PERSONAL DE LIMPIEZA | B49: ='C. Aux. Costos'!E16*'C. Aux. Costos'!D16 -> 2962590 | C49: =1/3 -> 0.33333333 | D49: =C49*B49*12 -> 11850360
C51: TOTAL | D51: =SUM(D43:D49) -> 136015992
A53: GASTOS EN MATERIALES DE FABRICACIÓN | D53: Total de la base año 1 | E53: Total base años regimen | F53: total año 1 | G53: total años regimen | H53: ESPECÍFICOS AÑO 1 | I53: ESPECÍFICOS REGIMEN
A54: Materiales para el mantenimiento | B54: 0.01 | C54: Del valor de los BdU que requieren mantenimiento | D54: ='E-Inv AF y Am'!D11+'E-Inv AF y Am'!D13+'E-Inv AF y Am'!B14+'E-Inv AF y Am'!B16*0.15+'E-Inv AF y Am'!B17/3+'E-Inv AF y Am'!B18/3 -> 8.0658396e+08 | E54: =D54 -> 8.0658396e+08 | F54: =D54*B54 -> 8065839.6 | G54: =E54*B54 -> 8065839.6 | H54: =F54/'CÁLCULOS MP'!$B$89 -> 217.94265 | I54: =G54/'CÁLCULOS MP'!$B$90 -> 180.04106
A55: Repuestos | B55: 0.016 | C55: valor de maquinaria | D55: ='E-Inv AF y Am'!D11+'E-Inv AF y Am'!D13 -> 790640500 | E55: =D55 -> 790640500 | F55: =D55*B55 -> 12650248 | G55: =E55*B55 -> 12650248 | H55: =F55/'CÁLCULOS MP'!$B$89 -> 341.81545 | I55: =G55/'CÁLCULOS MP'!$B$90 -> 282.37161
...

Sheet CÁLCULOS MP
G1: Tipo de cambio | H1: =InfoInicial!B31 -> 1300
A2: Componente | B2: Material | C2: COSTO | D2: um | E2: Uso en | F2: Link
A3: Barra de Acero Inoxidable 304 d28,6 | B3: Acero Inoxidable 304 | C3: =(125775/50)/H1 -> 1.935 | D3: USD/KG | E3: Maneta | F3: https://www.famiq.com.ar/producto/?sub-familia%5B%5D=barras-redondas&sub-familia%5B%5D=barras-cuadradas&sub-familia%5B%5D=barras-hexagonales&nodo=3&bloqueHome=1&caracteristica_calidad=304-304l&caracteristica_diametro-mm%5B%5D=28-6&tipoCatalogo=normal&caracteristica_forma=redonda
A4: Perno con Cabezal para Palanca | B4: Acero Inoxidable 304 | D4: USD/UN | E4: Palanca maneta | F4: https://articulo.mercadolibre.com.ar/MLA-2127138792-perno-de-carro-de-acero-inoxidable-x-2-pulgadas-color-50-_JM#polycard_client=search-nordic&search_layout=stack&position=6&type=item&tracking_id=c9927400-b1e2-4bb3-9053-b564420e0969
A5: Barra de Acero Inoxidable 304 d9,52 | B5: Acero Inoxidable 304 | C5: =6/1.5 -> 4 | D5: USD/KG | E5: Palanca maneta | F5: https://www.famiq.com.ar/producto/?sub-familia=barras-redondas&nodo=S155&caracteristica_diametro-mm%5B%5D=9-52&caracteristica_calidad=304-304l&tipoCatalogo=resumen
A6: Resorte Maneta | B6: Acero Inoxidable 302 | C6: =(12000/4)/H1 -> 2.3076923 | D6: USD/UN | E6: Maneta | F6: https://www.mercadolibre.com.ar/resortes-acero-inoxidable-8mm-x-36-mm-alamb-06-pack-x-4-un/up/MLAU2133390517#polycard_client=search-nordic&wid=MLA1454465469&search_layout=stack&position=9&type=product&tracking_id=4c9ff310-1477-44f8-ab8d-150edac1f232&sid=search
A7: Casquilo de Maneta | B7: Acero Inoxidable 304 | C7: =3.68/2 -> 1.84 | D7: USD/UN | E7: Maneta | F7: https://www.famiq.com.ar/producto/?nombreEs=CASQUILLO%20PARA%20MANETA%202%20POSICIONES%20NACIONAL%20304%2025.4%20a%20101.6%20mm&sub-familia=repuestos-de-valvulas-mariposa&tipoCatalogo=resumen
A8: Tapón Plástico Maneta | B8: PTFE con base EPDM | C8: =1.3*1.16/2 -> 0.754 | D8: USD/UN | E8: Maneta | F8: https://repuestos.caldereriamanzano.net/producto/tapon-para-maneta-de-valvula-ref-014736/?add-to-cart=5490
A9: Tapón de Buje | B9: PTFE con base EPDM | C9: 0.27 | D9: usd/un | F9: Consultado en Famiq | G9: 6133
A10: Buje Plástico para Clapeta | B10: PEEK (Polieter Éter Cetona) | C10: 0.27 | D10: USD/UN | F10: Consultado en Famiq | G10: 6141
A11: Forja de Tapa para Válvula | B11: Acero Inoxidable 304 | C11: 4 | D11: USD/KG | F11: Consultado en Famiq | G11: 3042
A12: Junta O-Ring | B12: Vitón(FMK) | C12: =6/2 -> 3 | D12: USD/UN | F12: https://www.famiq.com.ar/producto/?nombreEs=313224&sub-familia=junta-valvula-mariposa-mecanizada&tipoCatalogo=resumen
A13: Bulones 304 (Allen 6mm) | B13: Acero Inoxidable 304 | C13: =46.42/100/2 -> 0.2321 | D13: USD/UN | F13: https://www.famiq.com.ar/producto/?nombreEs=300468&sub-familia=allen-metricos-cabeza-cilindrica&tipoCatalogo=resumen
A14: Bulones 304 (Tuerca 6mm) | B14: Acero Inoxidable 305 | C14: =73.37/500/2 -> 0.07337 | D14: USD/UN | F14: https://www.famiq.com.ar/producto/?nombreEs=322124&sub-familia=tuercas-metricas&tipoCatalogo=resumen
A15: Arandelas 304 | B15: Acero Inoxidable 304 | C15: =52.61/200/2 -> 0.131525 | D15: USD/UN | F15: https://www.famiq.com.ar/producto/?nombreEs=300667&sub-familia=arandelas-planas&tipoCatalogo=resumen
A16: Forja de Clapeta | B16: Acero Inoxidable 304 | C16: 3 | D16: USD/KG | F16: Consultado en Famiq | G16: 8395
A18: TODOS NUESTROS DESPERDICIOS SON NO RECUPERABLES | D18: A LOS PRECIOS CONSULTADOS EN FAMIQ DESCONTAMOS UN MARGEN APROXIMADO DE 50% PARA MP Y DEL 100% PARA REPUESTOS
A20: CONSUMOS MP EN AÑOS EN RÉGIMEN
A21: FORJA PARA CUERPO
A22: Sección operativa | B22: Alimentacion (KG) | C22: Agregado | D22: Desperdicios | F22: Producción (KG)
D23: Recuperable | E23: No recuperable
A24: Mecanizado de cuerpo | B24: 67968.61 | C24: - | D24: - | E24: 0.15 | F24: 57773.32
A25: Rebabado de cuerpo | B25: 57773.32 | C25: - | D25: - | E25: 0.003 | F25: 44800/0,98*1.8*0.7=57600
A27: MP | C27: PRECIO UNIT (USD/KG) | D27: NECESIDAD | E27: TOTAL ANUAL
A28: Forja de Tapa para Válvula | B28: Acero Inoxidable 304 | C28: 4 | D28: =B24 -> 67968.61 | E28: =D28*C28 -> 271874.44 | F28: USD
A30: FORJA PARA CLAPETA
A31: Sección operativa | B31: Alimentacion (KG) | C31: Agregado | D31: Desperdicios | F31: Producción (KG)
D32: Recuperable | E32: No recuperable
A33: Mecanizado de forja y clapeta | B33: 4889.23 | C33: - | D33: - | E33: 0.15 | F33: 4155.84
A34: Pulido de clapeta | B34: 4122.53 | C34: - | D34: - | E34: 0.002 | F34: 4114.29
A36: MP | C36: PRECIO UNIT (USD/KG) | D36: NECESIDAD | E36: TOTAL ANUAL
A37: Forja de Clapeta | B37: Acero Inoxidable 304 | C37: 3 | D37: =B33 -> 4889.23 | E37: =D37*C37 -> 14667.69 | F37: USD
A39: BARRA PARA MANETA
A40: Sección operativa | B40: Alimentacion (KG) | C40: Agregado | D40: Desperdicios | F40: Producción (KG)
D41: Recuperable | E41: No recuperable
A42: Corte de barra | B42: 10569.508 | E42: 0.02 | F42: 10358.12
A43: Mecanizado de maneta | B43: 10358.12 | C43: - | D43: - | E43: 0.2 | F43: 8286.49
A44: Armado de maneta | B44: 8286.49 | C44: - | D44: - | E44: - | F44: 8286.49
A45: Soldadura de maneta | B45: 8286.49 | C45: - | D45: - | E45: - | F45: 8286.49
A46: Desbaste de maneta | B46: 8286.49 | C46: - | D46: - | E46: 0.005 | F46: 8245.06
...

Sheet E-InvAT
A1: ESTA PLANILLA PUEDE SER UTILIZADA SOLAMENTE PARA EL TRABAJO PRACTICO: | E1: =InfoInicial!E1 -> 6
A3: INVERSIONES EN ACTIVO DE TRABAJO
A4: Rubros | B4: Año 0 | C4: Año 1 | D4: Año 2 | E4: Año 3 | F4: Año 4 | G4: Año 5
A5: 1. Activo de Trabajo: (valor contable)
A6: a) Disponibilidad Mínima en Caja y Bancos: | B6: =C6*0.8 -> 63673280 | C6: ='C. Aux. Inv AT'!D6*0.02 -> 79591600 | D6: ='C. Aux. Inv AT'!E6*0.02 -> 89600000 | E6: ='C. Aux. Inv AT'!F6*0.02 -> 89600000 | F6: ='C. Aux. Inv AT'!G6*0.02 -> 89600000 | G6: ='C. Aux. Inv AT'!H6*0.02 -> 89600000
A7: b) Crédito por Ventas: | C7: ='C. Aux. Inv AT'!D6*30/365 -> 3.2708877e+08 | D7: ='C. Aux. Inv AT'!E6*30/365 -> 3.6821918e+08 | E7: ='C. Aux. Inv AT'!F6*30/365 -> 3.6821918e+08 | F7: ='C. Aux. Inv AT'!G6*30/365 -> 3.6821918e+08 | G7: ='C. Aux. Inv AT'!H6*30/365 -> 3.6821918e+08
A9: c) Bienes de cambio:
A10: Stock de materias prima: | B10: ='C. Aux. Inv AT'!C15 -> 3.4547793e+08 | C10: ='C. Aux. Inv AT'!D15 -> 4.8679663e+08 | D10: ='C. Aux. Inv AT'!E15 -> 4.8679663e+08 | E10: ='C. Aux. Inv AT'!F15 -> 4.8679663e+08 | F10: ='C. Aux. Inv AT'!G15 -> 4.8679663e+08 | G10: ='C. Aux. Inv AT'!H15 -> 4.8679663e+08
A11: Stock de materiales: | C11: ='C. Aux. Inv AT'!D23 -> 32905880 | D11: ='C. Aux. Inv AT'!E23 -> 33356484 | E11: ='C. Aux. Inv AT'!F23 -> 33356484 | F11: ='C. Aux. Inv AT'!G23 -> 33356484 | G11: ='C. Aux. Inv AT'!H23 -> 33356484
A12: Mercadería en curso y semielaborada | C12: ='E-Costos'!B43 -> 36298795 | D12: ='E-Costos'!C43 -> 35684429 | E12: ='E-Costos'!D43 -> 35684429 | F12: ='E-Costos'!E43 -> 35684429 | G12: ='E-Costos'!F43 -> 35684429
A13: Stock de elaborados: | C13: ='C. Aux. Inv AT'!D30 -> 21531998 | D13: ='C. Aux. Inv AT'!E30 -> 21545443 | E13: ='C. Aux. Inv AT'!F30 -> 21538902 | F13: ='C. Aux. Inv AT'!G30 -> 21538902 | G13: ='C. Aux. Inv AT'!H30 -> 21538902
A15: d) Total Activo de Trabajo, sin IVA: | B15: =SUM(B5:B14) -> 4.0915121e+08 | C15: =SUM(C5:C14) -> 9.8421367e+08 | D15: =SUM(D5:D14) -> 1.0352022e+09 | E15: =SUM(E5:E14) -> 1.0351956e+09 | F15: =SUM(F5:F14) -> 1.0351956e+09 | G15: =SUM(G5:G14) -> 1.0351956e+09
A16: 2. Menos:
A17: Amortizaciones en Mercadería en proceso | C17: ='E-Costos'!B34 -> 2084275.6 | D17: ='E-Costos'!C34 -> 1740277 | E17: ='E-Costos'!D34 -> 1740277 | F17: ='E-Costos'!E34 -> 1740277 | G17: ='E-Costos'!F34 -> 1740277
A18: Amortizaciones en Stock de elaborado | C18: ='C. Aux. Inv AT'!D40 -> 1897402.5 | D18: ='C. Aux. Inv AT'!E40 -> 1571095 | E18: ='C. Aux. Inv AT'!F40 -> 1571095 | F18: ='C. Aux. Inv AT'!G40 -> 1571095 | G18: ='C. Aux. Inv AT'!H40 -> 1571095
A19: Utilidades en Crédito por ventas | C19: =C7*'E-Costos'!B143 -> 89626648 | D19: =D7*'E-Costos'!C143 -> 1.0448391e+08 | E19: =E7*'E-Costos'!D143 -> 1.0451231e+08 | F19: =F7*'E-Costos'!E143 -> 1.0451202e+08 | G19: =G7*'E-Costos'!F143 -> 1.0451202e+08
A20: Amortizaciones en Crédito por ventas | C20: =('E-Inv AF y Am'!$D$59-C18-C17)*30/365 -> 17607342 | D20: =('E-Inv AF y Am'!$D$59-D18-D17)*30/365 -> 17662436 | E20: =('E-Inv AF y Am'!$D$59-E18-E17)*30/365 -> 17662436 | F20: =('E-Inv AF y Am'!$E$59-F18-F17)*30/365 -> 17662436 | G20: =('E-Inv AF y Am'!$E$59-G18-G17)*30/365 -> 17662436
A22: 3. Inversiones en Activo de Trabajo, sin IVA | B22: =B15-SUM(B17:B20) -> 4.0915121e+08 | C22: =C15-SUM(C17:C20) -> 8.72998e+08 | D22: =D15-SUM(D17:D20) -> 9.0974445e+08 | E22: =E15-SUM(E17:E20) -> 9.097095e+08 | F22: =F15-SUM(F17:F20) -> 9.0970979e+08 | G22: =G15-SUM(G17:G20) -> 9.0970979e+08
A24: 4. Incrementos de Activo de Trabajo | B24: =B15 -> 4.0915121e+08 | C24: =C15-B15 -> 5.7506245e+08 | D24: =D15-C15 -> 50988494 | E24: =E15-D15 -> -6541.3555 | F24: =F15-E15 -> 0 | G24: =G15-F15 -> 0
A25: Incrementos de Inversión en Activo de Trabajo | B25: =B22 -> 4.0915121e+08 | C25: =C22-B22 -> 4.6384678e+08 | D25: =D22-C22 -> 36746447 | E25: =E22-D22 -> -34947.426 | F25: =F22-E22 -> 292.91913 | G25: =G22-F22 -> 0
A27: 5. Incrementos IVA sobre Inversiones
A28: Crédito por Ventas
A29: Bienes de cambio:
A30: Stock de materia prima | B30: =B10*InfoInicial!B3 -> 72550366 | C30: =(C10-B10)*InfoInicial!B3 -> 29676925 | D30: =(D10-C10)*InfoInicial!C3 -> 0 | E30: =(E10-D10)*InfoInicial!D3 -> 0 | F30: =(F10-E10)*InfoInicial!E3 -> 0 | G30: =(G10-F10)*InfoInicial!F3 -> 0
A31: Stock de materiales | C31: =C11*InfoInicial!$B$3 -> 6910234.8 | D31: =(D11-C11)*InfoInicial!$B$3 -> 94626.725 | E31: =(E11-D11)*InfoInicial!$B$3 -> 0 | F31: =(F11-E11)*InfoInicial!$B$3 -> 0 | G31: =(G11-F11)*InfoInicial!$B$3 -> 0
A32: Mercadería en proceso | C32: =C12*InfoInicial!$B$3 -> 7622747 | D32: =(D12-C12)*InfoInicial!$B$3 -> -129016.92 | E32: =(E12-D12)*InfoInicial!$B$3 -> 0 | F32: =(F12-E12)*InfoInicial!$B$3 -> 0 | G32: =(G12-F12)*InfoInicial!$B$3 -> 0
A33: Stock de elaborados | C33: =C13*InfoInicial!$B$3 -> 4521719.5 | D33: =(D13-C13)*InfoInicial!$B$3 -> 2823.5777 | E33: =(E13-D13)*InfoInicial!$B$3 -> -1373.6847 | F33: =(F13-E13)*InfoInicial!$B$3 -> 0 | G33: =(G13-F13)*InfoInicial!$B$3 -> 0
A34: Total incrementos IVA sobre inversiones | B34: =SUM(B30:B33) -> 72550366 | C34: =SUM(C30:C33) -> 48731627 | D34: =SUM(D30:D33) -> -31566.622 | E34: =SUM(E30:E33) -> -1373.6847 | F34: =SUM(F30:F33) -> 0 | G34: =SUM(G30:G33) -> 0
A36: 6. Incrementos Inversiones en Activo de Trabajo | B36: =B34+B25 -> 4.8170158e+08 | C36: =C34+C25 -> 5.1257841e+08 | D36: =D34+D25 -> 36714881 | E36: =E34+E25 -> -36321.111 | F36: =F34+F25 -> 292.91913 | G36: =G34+G25 -> 0

Sheet C. Aux. Inv AT
B2: Plan de Ventas:
B4: Año | C4: 0 | D4: 1 | E4: 2 | F4: 3 | G4: 4 | H4: 5
B5: Cantidades | C5: 0 | D5: 36532 | E5: 44800 | F5: 44800 | G5: 44800 | H5: 44800
B6: Ingresos | C6: 0 | D6: 3979580000 | E6: 4480000000 | F6: 4480000000 | G6: 4480000000 | H6: 4480000000
B8: Para la disponibilidad minima de caja y bancos se tomara el 2% de los ingresos esperados por el plan de ventas y, para el año 0, el 80% de la disponibilidad del año 1
B10: La materia prima y los materiales se valuan a precio de mercado:
B12: Año | C12: 0 | D12: 1 | E12: 2 | F12: 3 | G12: 4 | H12: 5
B13: Stock Promedio MP | C13: 10715 | D13: 15098 | E13: 15098 | F13: 15098 | G13: 15098 | H13: 15098
B14: Precio Unitario | C14: ='CÁLCULOS MP'!$E$87*InfoInicial!$B$31 -> 32242.458 | D14: ='CÁLCULOS MP'!$E$87*InfoInicial!$B$31 -> 32242.458 | E14: ='CÁLCULOS MP'!$E$87*InfoInicial!$B$31 -> 32242.458 | F14: ='CÁLCULOS MP'!$E$87*InfoInicial!$B$31 -> 32242.458 | G14: ='CÁLCULOS MP'!$E$87*InfoInicial!$B$31 -> 32242.458 | H14: ='CÁLCULOS MP'!$E$87*InfoInicial!$B$31 -> 32242.458
B15: Total | C15: =C13*C14 -> 3.4547793e+08 | D15: =D13*D14 -> 4.8679663e+08 | E15: =E13*E14 -> 4.8679663e+08 | F15: =F13*F14 -> 4.8679663e+08 | G15: =G13*G14 -> 4.8679663e+08 | H15: =H13*H14 -> 4.8679663e+08
B17: Para el stock de materiales se estima el consumo de 6 meses para el area de producción y de 1 mes para las áreas de administración y comercialización
B19: Año | C19: 0 | D19: 1 | E19: 2 | F19: 3 | G19: 4 | H19: 5
B20: Producción | D20: ='AUX - COSTO DE PRODUC'!F59/2 -> 29232882 | E20: ='AUX - COSTO DE PRODUC'!$G$59/2 -> 28994486 | F20: ='AUX - COSTO DE PRODUC'!$G$59/2 -> 28994486 | G20: ='AUX - COSTO DE PRODUC'!$G$59/2 -> 28994486 | H20: ='AUX - COSTO DE PRODUC'!$G$59/2 -> 28994486
B21: Comercialización | D21: ='C. Aux. Costos'!C71/12 -> 3318996.7 | E21: ='C. Aux. Costos'!$E$71/12 -> 4007996.7 | F21: ='C. Aux. Costos'!$E$71/12 -> 4007996.7 | G21: ='C. Aux. Costos'!$E$71/12 -> 4007996.7 | H21: ='C. Aux. Costos'!$E$71/12 -> 4007996.7
B22: Administración | D22: ='C. Aux. Costos'!B71/12 -> 354001.2 | E22: ='C. Aux. Costos'!$D$71/12 -> 354001.2 | F22: ='C. Aux. Costos'!$D$71/12 -> 354001.2 | G22: ='C. Aux. Costos'!$D$71/12 -> 354001.2 | H22: ='C. Aux. Costos'!$D$71/12 -> 354001.2
B23: Total | D23: =SUM(D20:D22) -> 32905880 | E23: =SUM(E20:E22) -> 33356484 | F23: =SUM(F20:F22) -> 33356484 | G23: =SUM(G20:G22) -> 33356484 | H23: =SUM(H20:H22) -> 33356484
B25: La mercaderia en curso y SE y el stock de elaborados se evalua a costo de producción:
B27: Año | C27: 0 | D27: 1 | E27: 2 | F27: 3 | G27: 4 | H27: 5
B28: Costo de prod. unit. | D28: ='E-Costos'!B124 -> 45140.456 | E28: ='E-Costos'!C124 -> 45168.644 | F28: ='E-Costos'!D124 -> 45154.93 | G28: ='E-Costos'!E124 -> 45154.93 | H28: ='E-Costos'!F124 -> 45154.93
B29: Stock promedio PT | D29: 477 | E29: 477 | F29: 477 | G29: 477 | H29: 477
B30: Costo Stock prom. PT | D30: =D28*D29 -> 21531998 | E30: =E28*E29 -> 21545443 | F30: =F28*F29 -> 21538902 | G30: =G28*G29 -> 21538902 | H30: =H28*H29 -> 21538902
B32: Para las amortizaciones:
B34: Año | C34: 0 | D34: 1 | E34: 2 | F34: 3 | G34: 4 | H34: 5
B35: Alicuota Amort. Prod | D35: ='AUX - COSTO DE PRODUC'!$B$40 -> 1.4929805e+08 | E35: ='AUX - COSTO DE PRODUC'!$B$40 -> 1.4929805e+08 | F35: ='AUX - COSTO DE PRODUC'!$B$40 -> 1.4929805e+08 | G35: ='AUX - COSTO DE PRODUC'!$B$37 -> 1.4929805e+08 | H35: ='AUX - COSTO DE PRODUC'!$B$37 -> 1.4929805e+08
B36: Amort. Merc en Proc y SE | D36: ='E-Costos'!B34 -> 2084275.6 | E36: ='E-Costos'!C34 -> 1740277 | F36: ='E-Costos'!D34 -> 1740277 | G36: ='E-Costos'!E34 -> 1740277 | H36: ='E-Costos'!F34 -> 1740277
B37: Amort. Prod. Realiz. | D37: =D35-D36 -> 1.4721377e+08 | E37: =E35-E36 -> 1.4755777e+08 | F37: =F35-F36 -> 1.4755777e+08 | G37: =G35-G36 -> 1.4755777e+08 | H37: =H35-H36 -> 1.4755777e+08
B38: Producción | D38: 37009 | E38: 44800 | F38: 44800 | G38: 44800 | H38: 44800
B39: Amort. Prod. Realiz. Unit. | D39: =D37/D38 -> 3977.7831 | E39: =E37/E38 -> 3293.7003 | F39: =F37/F38 -> 3293.7003 | G39: =G37/G38 -> 3293.7003 | H39: =H37/H38 -> 3293.7003
B40: Amort. Stock PT | D40: =D39*D29 -> 1897402.5 | E40: =E39*E29 -> 1571095 | F40: =F39*F29 -> 1571095 | G40: =G39*G29 -> 1571095 | H40: =H39*H29 -> 1571095

Sheet E-Cal Inv.
A1: ESTA PLANILLA PUEDE SER UTILIZADA SOLAMENTE PARA EL TRABAJO PRACTICO: | G1: =InfoInicial!E1 -> 6
A3: Calendario de Inversiones
A4: Rubros | B4: Año 0: Preinversion | C4: Año 0: Instalación | D4: Año 1 | E4: Año 2 | F4: Año 3 | G4: Año 4 | H4: Año 5 | I4: Totales
A5: Inversiones en Activo Fijo
A6: Bienes de uso | C6: ='E-Inv AF y Am'!B21+'E-Inv AF y Am'!D21 -> 2.2250045e+09 | I6: =SUM(B6:H6) -> 2.2250045e+09
A7: Asimilables | B7: ='E-Inv AF y Am'!B24 -> 32500000 | C7: ='E-Inv AF y Am'!B33-'E-Inv AF y Am'!B24 -> 30159828 | D7: ='E-Inv AF y Am'!C33 -> 3.4546504e+08 | I7: =SUM(B7:H7) -> 4.0812486e+08
A8: Subtotal Activo Fijo | B8: =B7 -> 32500000 | C8: =C6+C7 -> 2.2551643e+09 | D8: =D7 -> 3.4546504e+08 | I8: =SUM(B8:H8) -> 2.6331293e+09
A10: Inversiones en A. de Trabajo
A11: Disp. mínimas C y B | C11: ='E-InvAT'!B6 -> 63673280 | D11: ='E-InvAT'!C6-'E-InvAT'!C11 -> 46685720 | E11: ='E-InvAT'!D6-'E-InvAT'!C6 -> 10008400 | I11: =SUM(B11:H11) -> 1.203674e+08
A12: Crédito por ventas | D12: ='E-InvAT'!C7-'E-InvAT'!C19-'E-InvAT'!C20 -> 2.1985478e+08 | E12: ='E-InvAT'!D7-'E-InvAT'!D19-'E-InvAT'!D20 -> 2.4607284e+08 | F12: ='E-InvAT'!E7-'E-InvAT'!E19-'E-InvAT'!E20 -> 2.4604443e+08 | G12: ='E-InvAT'!F7-'E-InvAT'!F19-'E-InvAT'!F20 -> 2.4604472e+08 | H12: ='E-InvAT'!G7-'E-InvAT'!G19-'E-InvAT'!G20 -> 2.4604472e+08 | I12: =SUM(B12:H12) -> 1.2040615e+09
A13: Bienes de cambio: | I13: =SUM(B13:H13) -> 0
A14: Stock de Materia Prima | C14: ='E-InvAT'!B10 -> 3.4547793e+08 | D14: ='E-InvAT'!C10-'E-InvAT'!B10 -> 1.4131869e+08 | E14: ='E-InvAT'!D10-'E-InvAT'!C10 -> 0 | F14: ='E-InvAT'!E10-'E-InvAT'!D10 -> 0 | G14: ='E-InvAT'!F10-'E-InvAT'!E10 -> 0 | H14: ='E-InvAT'!G10-'E-InvAT'!F10 -> 0 | I14: =SUM(B14:H14) -> 4.8679663e+08
A15: Stock de Materiales | D15: ='E-InvAT'!C11 -> 32905880 | E15: ='E-InvAT'!D11-'E-InvAT'!C11 -> 450603.45 | F15: ='E-InvAT'!E11-'E-InvAT'!D11 -> 0 | G15: ='E-InvAT'!F11-'E-InvAT'!E11 -> 0 | H15: ='E-InvAT'!G11-'E-InvAT'!F11 -> 0 | I15: =SUM(B15:H15) -> 33356484
A16: Mercadería en proceso | D16: ='E-InvAT'!C12 -> 36298795 | E16: ='E-InvAT'!D12-'E-InvAT'!C12 -> -614366.31 | F16: ='E-InvAT'!E12-'E-InvAT'!D12 -> 0 | G16: ='E-InvAT'!F12-'E-InvAT'!E12 -> 0 | H16: ='E-InvAT'!G12-'E-InvAT'!F12 -> 0 | I16: =SUM(B16:H16) -> 35684429
A17: Stock de Elaborados | D17: ='E-InvAT'!C13 -> 21531998 | E17: ='E-InvAT'!D13-'E-InvAT'!C13 -> 13445.608 | F17: ='E-InvAT'!E13-'E-InvAT'!D13 -> -6541.3555 | G17: ='E-InvAT'!F13-'E-InvAT'!E13 -> 0 | H17: ='E-InvAT'!G13-'E-InvAT'!F13 -> 0 | I17: =SUM(B17:H17) -> 21538902
A18: Subtotal Activo Trabajo | C18: =SUM(C11:C17) -> 4.0915121e+08 | D18: =SUM(D11:D17) -> 4.9859586e+08 | E18: =SUM(E11:E17) -> 2.5593092e+08 | F18: =SUM(F11:F17) -> 2.4603789e+08 | G18: =SUM(G11:G17) -> 2.4604472e+08 | H18: =SUM(H11:H17) -> 2.4604472e+08 | I18: =SUM(B18:H18) -> 1.9018053e+09
I19: =SUM(B19:H19) -> 0
A20: IVA: | I20: =SUM(B20:H20) -> 0
A21: por inversión A. Fijo | B21: =B8*InfoInicial!$B$3 -> 6825000 | C21: =C8*InfoInicial!$B$3 -> 4.735845e+08 | D21: =D8*InfoInicial!$B$3 -> 72547658 | E21: =E8*InfoInicial!$B$3 -> 0 | F21: =F8*InfoInicial!$B$3 -> 0 | G21: =G8*InfoInicial!$B$3 -> 0 | H21: =H8*InfoInicial!$B$3 -> 0 | I21: =SUM(B21:H21) -> 5.5295716e+08
A22: por inversión A. T. | C22: ='E-InvAT'!B34 -> 72550366 | D22: ='E-InvAT'!C34 -> 48731627 | E22: ='E-InvAT'!D34 -> -31566.622 | F22: ='E-InvAT'!E34 -> -1373.6847 | G22: ='E-InvAT'!F34 -> 0 | H22: ='E-InvAT'!G34 -> 0 | I22: =SUM(B22:H22) -> 1.2124905e+08
A23: Subtotal IVA Inversión | B23: =SUM(B21:B22) -> 6825000 | C23: =SUM(C21:C22) -> 5.4613487e+08 | D23: =SUM(D21:D22) -> 1.2127928e+08 | E23: =SUM(E21:E22) -> -31566.622 | F23: =SUM(F21:F22) -> -1373.6847 | G23: =SUM(G21:G22) -> 0 | H23: =SUM(H21:H22) -> 0 | I23: =SUM(B23:H23) -> 6.7420621e+08
I24: =SUM(B24:H24) -> 0
A25: Inversiones Totales | B25: =B8+B18+B23 -> 39325000 | C25: =C8+C18+C23 -> 3.2104504e+09 | D25: =D8+D18+D23 -> 9.6534018e+08 | E25: =E8+E18+E23 -> 2.5589935e+08 | F25: =F8+F18+F23 -> 2.4603651e+08 | G25: =G8+G18+G23 -> 2.4604472e+08 | H25: =H8+H18+H23 -> 2.4604472e+08 | I25: =SUM(B25:H25) -> 5.2091409e+09
C34: inversion en cred x vta = | E34: Valor contable - Utilidad - amortiz totales
E36: Valor contable = | F36: Ventas anuales/dias año * plazo credito

Sheet E-IVA 
A1: ESTA PLANILLA PUEDE SER UTILIZADA SOLAMENTE PARA EL TRABAJO PRACTICO: | G1: =InfoInicial!E1 -> 6
A2: IVA plan de Explotación, Cancelación del Credito Fiscal y pago al Fisco por IVA
B3: TOTALES PARA LAS TRES AREAS
A4: Rubros | B4: Año 0 | C4: Año 1 | D4: Año 2 | E4: Año 3 | F4: Año 4 | G4: Año 5
A5: Rubros que abonan IVA
A6: Materia Prima | C6: ='E-Costos'!B112*InfoInicial!$B$3 -> 3.1286169e+08 | D6: ='E-Costos'!C112*InfoInicial!$B$3 -> 3.0333704e+08 | E6: ='E-Costos'!D112*InfoInicial!$B$3 -> 3.0333704e+08 | F6: ='E-Costos'!E112*InfoInicial!$B$3 -> 3.0333704e+08 | G6: ='E-Costos'!F112*InfoInicial!$B$3 -> 3.0333704e+08
A7: Materiales | C7: ='E-Costos'!B12*InfoInicial!$B$3 -> 12277811 | D7: ='E-Costos'!C12*InfoInicial!$B$3 -> 12177684 | E7: ='E-Costos'!D12*InfoInicial!$B$3 -> 12177684 | F7: ='E-Costos'!E12*InfoInicial!$B$3 -> 12177684 | G7: ='E-Costos'!F12*InfoInicial!$B$3 -> 12177684
A8: Energía eléctrica | C8: ='E-Costos'!B13*InfoInicial!$B$3 -> 9905245.5 | D8: ='E-Costos'!C13*InfoInicial!$B$3 -> 9409983.2 | E8: ='E-Costos'!D13*InfoInicial!$B$3 -> 9409983.2 | F8: ='E-Costos'!E13*InfoInicial!$B$3 -> 9409983.2 | G8: ='E-Costos'!F13*InfoInicial!$B$3 -> 9409983.2
A9: Combustibles | C9: =('E-Costos'!B14)*InfoInicial!$B$3 -> 0 | D9: ='E-Costos'!C14*InfoInicial!$B$3 -> 0 | E9: ='E-Costos'!D14*InfoInicial!$B$3 -> 0 | F9: ='E-Costos'!E14*InfoInicial!$B$3 -> 0 | G9: ='E-Costos'!F14*InfoInicial!$B$3 -> 0
A10: Seguros | C10: =('E-Costos'!B19)*InfoInicial!$B$3 -> 5247917.5 | D10: =('E-Costos'!C19)*InfoInicial!$B$3 -> 5247917.5 | E10: =('E-Costos'!D19)*InfoInicial!$B$3 -> 5247917.5 | F10: =('E-Costos'!E19)*InfoInicial!$B$3 -> 5247917.5 | G10: =('E-Costos'!F19)*InfoInicial!$B$3 -> 5247917.5
A11: Varios | C11: 0 | D11: 0 | E11: 0 | F11: 0 | G11: 0
A12: Subtotal | C12: =SUM(C6:C11) -> 3.4029266e+08 | D12: =SUM(D6:D11) -> 3.3017263e+08 | E12: =SUM(E6:E11) -> 3.3017263e+08 | F12: =SUM(F6:F11) -> 3.3017263e+08 | G12: =SUM(G6:G11) -> 3.3017263e+08
A13: Menos: Puesta en marcha | C13: =('E-Costos'!G31+'E-Costos'!G36+'E-Costos'!G37)*InfoInicial!B3 -> 74284809 | D13: 0 | E13: 0 | F13: 0 | G13: 0
A14: (s/mano de obra directa)
A15: Merc. en proceso | C15: =('E-Costos'!B31+'E-Costos'!B36+'E-Costos'!B37)*InfoInicial!$B$3 -> 5727294.9 | D15: =('E-Costos'!C31+'E-Costos'!C36+'E-Costos'!C37)*InfoInicial!$B$3-C15 -> -47583.402 | E15: =('E-Costos'!C31+'E-Costos'!C36+'E-Costos'!C37)*InfoInicial!$B$3-('E-Costos'!C31+'E-Costos'!C36+'E-Costos'!C37)*InfoInicial!$B$3 -> 0 | F15: =('E-Costos'!D31+'E-Costos'!D36+'E-Costos'!D37)*InfoInicial!$B$3-('E-Costos'!D31+'E-Costos'!D36+'E-Costos'!D37)*InfoInicial!$B$3 -> 0 | G15: =('E-Costos'!E31+'E-Costos'!E36+'E-Costos'!E37)*InfoInicial!$B$3-('E-Costos'!E31+'E-Costos'!E36+'E-Costos'!E37)*InfoInicial!$B$3 -> 0
A16: Stock elaborados | C16: ='CÁLCULOS MP'!B92*('E-Costos'!B7+'E-Costos'!B12+'E-Costos'!B13+'E-Costos'!B19)/'CÁLCULOS MP'!B89*InfoInicial!B3 -> 4110103.5 | D16: ='CÁLCULOS MP'!B92*('E-Costos'!C7+'E-Costos'!C12+'E-Costos'!C13+'E-Costos'!C19)/'CÁLCULOS MP'!B90*InfoInicial!B3-C16 -> -815747.16 | E16: ='CÁLCULOS MP'!$B$92*('E-Costos'!D7+'E-Costos'!D12+'E-Costos'!D13+'E-Costos'!D19)/'CÁLCULOS MP'!$B$90*InfoInicial!$B$3-'CÁLCULOS MP'!$B$92*('E-Costos'!C7+'E-Costos'!C12+'E-Costos'!C13+'E-Costos'!C19)/'CÁLCULOS MP'!$B$90*InfoInicial!$B$3 -> 0 | F16: ='CÁLCULOS MP'!$B$92*('E-Costos'!E7+'E-Costos'!E12+'E-Costos'!E13+'E-Costos'!E19)/'CÁLCULOS MP'!$B$90*InfoInicial!$B$3-'CÁLCULOS MP'!$B$92*('E-Costos'!D7+'E-Costos'!D12+'E-Costos'!D13+'E-Costos'!D19)/'CÁLCULOS MP'!$B$90*InfoInicial!$B$3 -> 0 | G16: ='CÁLCULOS MP'!$B$92*('E-Costos'!F7+'E-Costos'!F12+'E-Costos'!F13+'E-Costos'!F19)/'CÁLCULOS MP'!$B$90*InfoInicial!$B$3-'CÁLCULOS MP'!$B$92*('E-Costos'!E7+'E-Costos'!E12+'E-Costos'!E13+'E-Costos'!E19)/'CÁLCULOS MP'!$B$90*InfoInicial!$B$3 -> 0
A17: Total Area Producción | C17: =C12-C13-C15-C16 -> 2.5617046e+08 | D17: =D12-D13-D15-D16 -> 3.3103596e+08 | E17: =E12-E13-E15-E16 -> 3.3017263e+08 | F17: =F12-F13-F15-F16 -> 3.3017263e+08 | G17: =G12-G13-G15-G16 -> 3.3017263e+08
A18: Total Area Administración | C18: =('E-Costos'!B62+'E-Costos'!B63+'E-Costos'!B64+'E-Costos'!B69)*InfoInicial!$B$3 -> 1639418.4 | D18: =('E-Costos'!C62+'E-Costos'!C63+'E-Costos'!C64+'E-Costos'!C69)*InfoInicial!$B$3 -> 1614655.3 | E18: =('E-Costos'!D62+'E-Costos'!D63+'E-Costos'!D64+'E-Costos'!D69)*InfoInicial!$B$3 -> 1614655.3 | F18: =('E-Costos'!E62+'E-Costos'!E63+'E-Costos'!E64+'E-Costos'!E69)*InfoInicial!$B$3 -> 1614655.3 | G18: =('E-Costos'!F62+'E-Costos'!F63+'E-Costos'!F64+'E-Costos'!F69)*InfoInicial!$B$3 -> 1614655.3
A19: Total Area Comercialización | C19: =('E-Costos'!B83+'E-Costos'!B84+'E-Costos'!B85+'E-Costos'!B90)*InfoInicial!$B$3 -> 9111207 | D19: =('E-Costos'!C83+'E-Costos'!C84+'E-Costos'!C85+'E-Costos'!C90)*InfoInicial!$B$3 -> 10822724 | E19: =('E-Costos'!D83+'E-Costos'!D84+'E-Costos'!D85+'E-Costos'!D90)*InfoInicial!$B$3 -> 10822724 | F19: =('E-Costos'!E83+'E-Costos'!E84+'E-Costos'!E85+'E-Costos'!E90)*InfoInicial!$B$3 -> 10822724 | G19: =('E-Costos'!F83+'E-Costos'!F84+'E-Costos'!F85+'E-Costos'!F90)*InfoInicial!$B$3 -> 10822724
A21: IVA total abonado por insumos | C21: =SUM(C17:C19) -> 2.6692108e+08 | D21: =SUM(D17:D19) -> 3.4347334e+08 | E21: =SUM(E17:E19) -> 3.4261001e+08 | F21: =SUM(F17:F19) -> 3.4261001e+08 | G21: =SUM(G17:G19) -> 3.4261001e+08
A22: IVA total cobrado por ventas | C22: ='C. Aux. Costos'!O5*InfoInicial!$B$3 -> 843889200 | D22: ='C. Aux. Costos'!P5*InfoInicial!$B$3 -> 1034880000 | E22: ='C. Aux. Costos'!Q5*InfoInicial!$B$3 -> 1034880000 | F22: ='C. Aux. Costos'!R5*InfoInicial!$B$3 -> 1034880000 | G22: ='C. Aux. Costos'!S5*InfoInicial!$B$3 -> 1034880000
A23: a) IVA diferencia | C23: =C22-C21 -> 5.7696812e+08 | D23: =D22-D21 -> 6.9140666e+08 | E23: =E22-E21 -> 6.9226999e+08 | F23: =F22-F21 -> 6.9226999e+08 | G23: =G22-G21 -> 6.9226999e+08
A25: b) Crédito Fiscal Anterior | B25: 0 | C25: =B27 -> 5.5295987e+08 | D25: =C27 -> 97271035 | E25: =D27 -> 0 | F25: =E27 -> 0 | G25: =F27 -> 0
A26: c) Crédito Fiscal del Año | B26: =SUM('E-Cal Inv.'!B23:C23) -> 5.5295987e+08 | C26: ='E-Cal Inv.'!D23 -> 1.2127928e+08 | D26: ='E-Cal Inv.'!E23 -> -31566.622 | E26: ='E-Cal Inv.'!F23 -> -1373.6847 | F26: ='E-Cal Inv.'!G23 -> 0 | G26: ='E-Cal Inv.'!H23 -> 0
